<?xml version="1.0" ?>
<!-- =================================================================================== -->
<!-- |    This document was autogenerated by xacro from Drilling.xacro                 | -->
<!-- |    EDITING THIS FILE BY HAND IS NOT RECOMMENDED                                 | -->
<!-- =================================================================================== -->
<robot name="Drilling">
  <material name="silver">
    <color rgba="0.700 0.700 0.700 1.000"/>
  </material>
  <transmission name="Rev1_tran">
    <type>transmission_interface/SimpleTransmission</type>
    <joint name="Rev1">
      <hardwareInterface>hardware_interface/EffortJointInterface</hardwareInterface>
    </joint>
    <actuator name="Rev1_actr">
      <hardwareInterface>hardware_interface/EffortJointInterface</hardwareInterface>
      <mechanicalReduction>1</mechanicalReduction>
    </actuator>
  </transmission>
  <transmission name="Rev2_tran">
    <type>transmission_interface/SimpleTransmission</type>
    <joint name="Rev2">
      <hardwareInterface>hardware_interface/EffortJointInterface</hardwareInterface>
    </joint>
    <actuator name="Rev2_actr">
      <hardwareInterface>hardware_interface/EffortJointInterface</hardwareInterface>
      <mechanicalReduction>1</mechanicalReduction>
    </actuator>
  </transmission>
  <transmission name="Rev3_tran">
    <type>transmission_interface/SimpleTransmission</type>
    <joint name="Rev3">
      <hardwareInterface>hardware_interface/EffortJointInterface</hardwareInterface>
    </joint>
    <actuator name="Rev3_actr">
      <hardwareInterface>hardware_interface/EffortJointInterface</hardwareInterface>
      <mechanicalReduction>1</mechanicalReduction>
    </actuator>
  </transmission>
  <transmission name="Rev4_tran">
    <type>transmission_interface/SimpleTransmission</type>
    <joint name="Rev4">
      <hardwareInterface>hardware_interface/EffortJointInterface</hardwareInterface>
    </joint>
    <actuator name="Rev4_actr">
      <hardwareInterface>hardware_interface/EffortJointInterface</hardwareInterface>
      <mechanicalReduction>1</mechanicalReduction>
    </actuator>
  </transmission>
  <transmission name="Rev5_tran">
    <type>transmission_interface/SimpleTransmission</type>
    <joint name="Rev5">
      <hardwareInterface>hardware_interface/EffortJointInterface</hardwareInterface>
    </joint>
    <actuator name="Rev5_actr">
      <hardwareInterface>hardware_interface/EffortJointInterface</hardwareInterface>
      <mechanicalReduction>1</mechanicalReduction>
    </actuator>
  </transmission>
  <transmission name="Rev6_tran">
    <type>transmission_interface/SimpleTransmission</type>
    <joint name="Rev6">
      <hardwareInterface>hardware_interface/EffortJointInterface</hardwareInterface>
    </joint>
    <actuator name="Rev6_actr">
      <hardwareInterface>hardware_interface/EffortJointInterface</hardwareInterface>
      <mechanicalReduction>1</mechanicalReduction>
    </actuator>
  </transmission>
  <transmission name="Rev10_tran">
    <type>transmission_interface/SimpleTransmission</type>
    <joint name="Rev10">
      <hardwareInterface>hardware_interface/EffortJointInterface</hardwareInterface>
    </joint>
    <actuator name="Rev10_actr">
      <hardwareInterface>hardware_interface/EffortJointInterface</hardwareInterface>
      <mechanicalReduction>1</mechanicalReduction>
    </actuator>
  </transmission>
  <transmission name="Rev11_tran">
    <type>transmission_interface/SimpleTransmission</type>
    <joint name="Rev11">
      <hardwareInterface>hardware_interface/EffortJointInterface</hardwareInterface>
    </joint>
    <actuator name="Rev11_actr">
      <hardwareInterface>hardware_interface/EffortJointInterface</hardwareInterface>
      <mechanicalReduction>1</mechanicalReduction>
    </actuator>
  </transmission>
  <gazebo>
    <plugin filename="libgazebo_ros_control.so" name="control"/>
  </gazebo>
  <gazebo reference="base_link">
    <material>Gazebo/Silver</material>
    <mu1>0.2</mu1>
    <mu2>0.2</mu2>
    <selfCollide>true</selfCollide>
    <gravity>true</gravity>
  </gazebo>
  <gazebo reference="Component2_1">
    <material>Gazebo/Silver</material>
    <mu1>0.2</mu1>
    <mu2>0.2</mu2>
    <selfCollide>true</selfCollide>
  </gazebo>
  <gazebo reference="Component2_2">
    <material>Gazebo/Silver</material>
    <mu1>0.2</mu1>
    <mu2>0.2</mu2>
    <selfCollide>true</selfCollide>
  </gazebo>
  <gazebo reference="Component2_3">
    <material>Gazebo/Silver</material>
    <mu1>0.2</mu1>
    <mu2>0.2</mu2>
    <selfCollide>true</selfCollide>
  </gazebo>
  <gazebo reference="Component2_4">
    <material>Gazebo/Silver</material>
    <mu1>0.2</mu1>
    <mu2>0.2</mu2>
    <selfCollide>true</selfCollide>
  </gazebo>
  <gazebo reference="Component2_5">
    <material>Gazebo/Silver</material>
    <mu1>0.2</mu1>
    <mu2>0.2</mu2>
    <selfCollide>true</selfCollide>
  </gazebo>
  <gazebo reference="Component2_6">
    <material>Gazebo/Silver</material>
    <mu1>0.2</mu1>
    <mu2>0.2</mu2>
    <selfCollide>true</selfCollide>
  </gazebo>
  <gazebo reference="Component3_1">
    <material>Gazebo/Silver</material>
    <mu1>0.2</mu1>
    <mu2>0.2</mu2>
    <selfCollide>true</selfCollide>
  </gazebo>
  <gazebo reference="Component5_1">
    <material>Gazebo/Silver</material>
    <mu1>0.2</mu1>
    <mu2>0.2</mu2>
    <selfCollide>true</selfCollide>
  </gazebo>
  <gazebo reference="Component4_1">
    <material>Gazebo/Silver</material>
    <mu1>0.2</mu1>
    <mu2>0.2</mu2>
    <selfCollide>true</selfCollide>
  </gazebo>
  <link name="base_link">
    <inertial>
      <origin rpy="0 0 0" xyz="0.0007409944454271297 -0.00018575300431278248 -0.03004710734399212"/>
      <mass value="1.4011736369087806"/>
      <inertia ixx="0.027819" ixy="-0.0" ixz="0.0" iyy="0.021092" iyz="-0.0" izz="0.024068"/>
    </inertial>
    <visual>
      <origin rpy="0 0 0" xyz="0 0 0"/>
      <geometry>
        <mesh filename="package://Drilling_description/meshes/base_link.stl" scale="0.001 0.001 0.001"/>
      </geometry>
      <material name="silver"/>
    </visual>
    <collision>
      <origin rpy="0 0 0" xyz="0 0 0"/>
      <geometry>
        <mesh filename="package://Drilling_description/meshes/base_link.stl" scale="0.001 0.001 0.001"/>
      </geometry>
    </collision>
  </link>
  <link name="Component2_1">
    <inertial>
      <origin rpy="0 0 0" xyz="-9.957231572599312e-08 2.724718541069482e-07 0.02214285551193418"/>
      <mass value="0.02997397356005734"/>
      <inertia ixx="2.3e-05" ixy="-0.0" ixz="-0.0" iyy="7e-06" iyz="0.0" izz="1.9e-05"/>
    </inertial>
    <visual>
      <origin rpy="0 0 0" xyz="0.237414 0.137686 -0.022556"/>
      <geometry>
        <mesh filename="package://Drilling_description/meshes/Component2_1.stl" scale="0.001 0.001 0.001"/>
      </geometry>
      <material name="silver"/>
    </visual>
    <collision>
      <origin rpy="0 0 0" xyz="0.237414 0.137686 -0.022556"/>
      <geometry>
        <mesh filename="package://Drilling_description/meshes/Component2_1.stl" scale="0.001 0.001 0.001"/>
      </geometry>
    </collision>
  </link>
  <link name="Component2_2">
    <inertial>
      <origin rpy="0 0 0" xyz="-1.1702442880446445e-07 2.940560291930794e-07 0.022142855511934123"/>
      <mass value="0.02997397356005734"/>
      <inertia ixx="7e-06" ixy="0.0" ixz="-0.0" iyy="2.3e-05" iyz="-0.0" izz="1.9e-05"/>
    </inertial>
    <visual>
      <origin rpy="0 0 0" xyz="-0.000743 0.275186 -0.022556"/>
      <geometry>
        <mesh filename="package://Drilling_description/meshes/Component2_2.stl" scale="0.001 0.001 0.001"/>
      </geometry>
      <material name="silver"/>
    </visual>
    <collision>
      <origin rpy="0 0 0" xyz="-0.000743 0.275186 -0.022556"/>
      <geometry>
        <mesh filename="package://Drilling_description/meshes/Component2_2.stl" scale="0.001 0.001 0.001"/>
      </geometry>
    </collision>
  </link>
  <link name="Component2_3">
    <inertial>
      <origin rpy="0 0 0" xyz="-1.3098370804653925e-07 2.9405602910981266e-07 0.02214285551193418"/>
      <mass value="0.02997397356005734"/>
      <inertia ixx="7e-06" ixy="0.0" ixz="-0.0" iyy="2.3e-05" iyz="-0.0" izz="1.9e-05"/>
    </inertial>
    <visual>
      <origin rpy="0 0 0" xyz="-0.2389 0.137686 -0.022556"/>
      <geometry>
        <mesh filename="package://Drilling_description/meshes/Component2_3.stl" scale="0.001 0.001 0.001"/>
      </geometry>
      <material name="silver"/>
    </visual>
    <collision>
      <origin rpy="0 0 0" xyz="-0.2389 0.137686 -0.022556"/>
      <geometry>
        <mesh filename="package://Drilling_description/meshes/Component2_3.stl" scale="0.001 0.001 0.001"/>
      </geometry>
    </collision>
  </link>
  <link name="Component2_4">
    <inertial>
      <origin rpy="0 0 0" xyz="-1.5256788316042602e-07 2.9056319558740107e-07 0.02214285551193413"/>
      <mass value="0.02997397356005734"/>
      <inertia ixx="2.3e-05" ixy="-0.0" ixz="0.0" iyy="7e-06" iyz="-0.0" izz="1.9e-05"/>
    </inertial>
    <visual>
      <origin rpy="0 0 0" xyz="-0.2389 -0.137314 -0.022556"/>
      <geometry>
        <mesh filename="package://Drilling_description/meshes/Component2_4.stl" scale="0.001 0.001 0.001"/>
      </geometry>
      <material name="silver"/>
    </visual>
    <collision>
      <origin rpy="0 0 0" xyz="-0.2389 -0.137314 -0.022556"/>
      <geometry>
        <mesh filename="package://Drilling_description/meshes/Component2_4.stl" scale="0.001 0.001 0.001"/>
      </geometry>
    </collision>
  </link>
  <link name="Component2_5">
    <inertial>
      <origin rpy="0 0 0" xyz="-1.3511576994133367e-07 2.6897902039024757e-07 0.02214285551193417"/>
      <mass value="0.02997397356005734"/>
      <inertia ixx="7e-06" ixy="0.0" ixz="0.0" iyy="2.3e-05" iyz="0.0" izz="1.9e-05"/>
    </inertial>
    <visual>
      <origin rpy="0 0 0" xyz="-0.000743 -0.274814 -0.022556"/>
      <geometry>
        <mesh filename="package://Drilling_description/meshes/Component2_5.stl" scale="0.001 0.001 0.001"/>
      </geometry>
      <material name="silver"/>
    </visual>
    <collision>
      <origin rpy="0 0 0" xyz="-0.000743 -0.274814 -0.022556"/>
      <geometry>
        <mesh filename="package://Drilling_description/meshes/Component2_5.stl" scale="0.001 0.001 0.001"/>
      </geometry>
    </collision>
  </link>
  <link name="Component2_6">
    <inertial>
      <origin rpy="0 0 0" xyz="-1.2115649092314662e-07 2.6897902050126987e-07 0.022142855511934144"/>
      <mass value="0.02997397356005734"/>
      <inertia ixx="7e-06" ixy="0.0" ixz="0.0" iyy="2.3e-05" iyz="0.0" izz="1.9e-05"/>
    </inertial>
    <visual>
      <origin rpy="0 0 0" xyz="0.237414 -0.137314 -0.022556"/>
      <geometry>
        <mesh filename="package://Drilling_description/meshes/Component2_6.stl" scale="0.001 0.001 0.001"/>
      </geometry>
      <material name="silver"/>
    </visual>
    <collision>
      <origin rpy="0 0 0" xyz="0.237414 -0.137314 -0.022556"/>
      <geometry>
        <mesh filename="package://Drilling_description/meshes/Component2_6.stl" scale="0.001 0.001 0.001"/>
      </geometry>
    </collision>
  </link>
  <link name="Component3_1">
    <inertial>
      <origin rpy="0 0 0" xyz="7.912531740927875e-12 -1.9775532191693154e-12 -0.030064400329856678"/>
      <mass value="0.047497097171063256"/>
      <inertia ixx="1.4e-05" ixy="0.0" ixz="0.0" iyy="1.2e-05" iyz="0.0" izz="9e-06"/>
    </inertial>
    <visual>
      <origin rpy="0 0 0" xyz="-0.0525 0.0 -0.0"/>
      <geometry>
        <mesh filename="package://Drilling_description/meshes/Component3_1.stl" scale="0.001 0.001 0.001"/>
      </geometry>
      <material name="silver"/>
    </visual>
    <collision>
      <origin rpy="0 0 0" xyz="-0.0525 0.0 -0.0"/>
      <geometry>
        <mesh filename="package://Drilling_description/meshes/Component3_1.stl" scale="0.001 0.001 0.001"/>
      </geometry>
    </collision>
  </link>
  <link name="Component5_1">
    <inertial>
      <origin rpy="0 0 0" xyz="3.705164159425317e-12 -7.924302410511538e-14 -0.017021191173281436"/>
      <mass value="0.00021466150433616682"/>
      <inertia ixx="0.0" ixy="-0.0" ixz="0.0" iyy="0.0" iyz="0.0" izz="0.0"/>
    </inertial>
    <visual>
      <origin rpy="0 0 0" xyz="-0.00025 0.0 0.2696"/>
      <geometry>
        <mesh filename="package://Drilling_description/meshes/Component5_1.stl" scale="0.001 0.001 0.001"/>
      </geometry>
      <material name="silver"/>
    </visual>
    <collision>
      <origin rpy="0 0 0" xyz="-0.00025 0.0 0.2696"/>
      <geometry>
        <mesh filename="package://Drilling_description/meshes/Component5_1.stl" scale="0.001 0.001 0.001"/>
      </geometry>
    </collision>
  </link>
  <link name="Component4_1">
    <inertial>
      <origin rpy="0 0 0" xyz="-0.0519070291202938 -0.017750708854665134 -0.09645899486628742"/>
      <mass value="0.4016667315756196"/>
      <inertia ixx="0.001699" ixy="0.0" ixz="-1.3e-05" iyy="0.001693" iyz="0.0" izz="0.000111"/>
    </inertial>
    <visual>
      <origin rpy="0 0 0" xyz="-0.0525 -0.01775 0.0446"/>
      <geometry>
        <mesh filename="package://Drilling_description/meshes/Component4_1.stl" scale="0.001 0.001 0.001"/>
      </geometry>
      <material name="silver"/>
    </visual>
    <collision>
      <origin rpy="0 0 0" xyz="-0.0525 -0.01775 0.0446"/>
      <geometry>
        <mesh filename="package://Drilling_description/meshes/Component4_1.stl" scale="0.001 0.001 0.001"/>
      </geometry>
    </collision>
  </link>
  <joint name="Rev1" type="continuous">
    <origin rpy="0 0 0" xyz="-0.237414 -0.137686 0.022556"/>
    <parent link="base_link"/>
    <child link="Component2_1"/>
    <axis xyz="0.0 0.0 1.0"/>
  </joint>
  <joint name="Rev2" type="continuous">
    <origin rpy="0 0 0" xyz="0.000743 -0.275186 0.022556"/>
    <parent link="base_link"/>
    <child link="Component2_2"/>
    <axis xyz="0.0 0.0 1.0"/>
  </joint>
  <joint name="Rev3" type="continuous">
    <origin rpy="0 0 0" xyz="0.2389 -0.137686 0.022556"/>
    <parent link="base_link"/>
    <child link="Component2_3"/>
    <axis xyz="0.0 0.0 1.0"/>
  </joint>
  <joint name="Rev4" type="continuous">
    <origin rpy="0 0 0" xyz="0.2389 0.137314 0.022556"/>
    <parent link="base_link"/>
    <child link="Component2_4"/>
    <axis xyz="0.0 0.0 1.0"/>
  </joint>
  <joint name="Rev5" type="continuous">
    <origin rpy="0 0 0" xyz="0.000743 0.274814 0.022556"/>
    <parent link="base_link"/>
    <child link="Component2_5"/>
    <axis xyz="0.0 0.0 1.0"/>
  </joint>
  <joint name="Rev6" type="continuous">
    <origin rpy="0 0 0" xyz="-0.237414 0.137314 0.022556"/>
    <parent link="base_link"/>
    <child link="Component2_6"/>
    <axis xyz="0.0 0.0 1.0"/>
  </joint>
  <joint name="Rigid7" type="fixed">
    <origin rpy="0 0 0" xyz="0.0525 0.0 0.0"/>
    <parent link="base_link"/>
    <child link="Component3_1"/>
  </joint>
  <joint name="Rev10" type="continuous">
    <origin rpy="0 0 0" xyz="-0.05225 -0.01775 -0.225"/>
    <parent link="Component4_1"/>
    <child link="Component5_1"/>
    <axis xyz="0.0 0.0 -1.0"/>
  </joint>
  <joint name="Rev11" type="revolute">
    <origin rpy="0 0 0" xyz="0.0 0.01775 -0.0446"/>
    <parent link="Component3_1"/>
    <child link="Component4_1"/>
    <axis xyz="0.0 1.0 0.0"/>
    <limit effort="100" lower="-1.570796" upper="0.436332" velocity="100"/>
  </joint>
</robot>
